Workbook

Sheet Identificación del Instrumento
A1: IDENTIFICACIÓN DEL INSTRUMENTO VERIFICADO | S1: Buenos Aires
D2: dia (n°) | E2: mes (texto) | F2: año (n°) | I2: Fecha verificación: | J2: =CONCATENATE(D3, " de ",E3, " de ",F3) | S2: Catamarca
C3: Fecha: | D3: 20 | E3: octubre | F3: 2025 | I3: Fecha vencimiento: | J3: =CONCATENATE(D3, " de ",E3, " de ",F3+2)
A4: Número de O.T.: | B4: 307-62136 | C4: 91997 | D4: Santa Rosa de Conlara | S4: Chaco
A5: =IF(ISBLANK(B17),"",VLOOKUP('Identificación del Instrumento'!$B$17,$L$28:$Q$31,6,FALSE)) | B5: 91997 | C5: Provincia: | D5: San Luis | S5: Chubut
S6: Ciudad Autónoma de Buenos Aires
A7: En el día de la fecha constituido el técnico autorizado que firma al pie de la presente, en la razón social que mas abajo se cita, procede a efectuar el control del instrumento de medición cuyas características se detallan, obteniéndose los resultados que corren agregados en planilla adjunta a la presente. | S7: Córdoba
L8: VERIFICACION PRIMITIVA | M8: 2 | S8: Corrientes
L9: VERIFICACIÓN PERIÓDICA | M9: 1 | S9: Entre Ríos
L10: APROBACIÓN DE MODELO DE EFECTO LIMITADO | S10: Formosa
L11: PRIMITIVA DE ÚNICA UNIDAD | S11: Jujuy
B12: Ente de control de rutas provinciales | L12: PRIMITIVA DE ÚNICA UNIDAD | S12: La Pampa
B13: Autopista de las serranías puntanas Km 783. San luis | L13: PRIMITIVA DE ÚNICA UNIDAD | S13: La Rioja
A14: Razón social (Propietario): | C14: Ente Control de Rutas Provinciales | L14: PRIMITIVA DE INSTRUMENTO REPARADO A NUEVO | S14: Mendoza
A15: Domicilio (Fiscal): | B15: LAVALLE Y ARISTÓBULO DEL VALLE - ESQUINA, | S15: Misiones
A16: =CONCATENATE(IF(F16="Ciudad Autónoma de Buenos Aires","","Localidad: ")) | B16: San Luis | E16: =CONCATENATE(IF(F16="Ciudad Autónoma de Buenos Aires"," Localidad: "," Provincia: ")) | F16: San Luis | S16: Neuquén
A17: Tipo de Verificación: | B17: VERIFICACIÓN PERIÓDICA | E17: Tolerancia: | F17: VERIFICACIÓN PERIÓDICA | S17: Río Negro
A18: Lugar propio de instalación del instrumento (*): | C18: Zona de pesaje | S18: Salta
A19: Domicilio (*): | B19: Ruta 55 km 921 | I19: =AND(ISBLANK(F20),ISBLANK(B19)) | S19: San Juan
A20: =CONCATENATE(IF(F20="Ciudad Autónoma de Buenos Aires","","Localidad (*): ")) | B20: Ruta 55 km 921 | E20: =CONCATENATE(IF(F20="Ciudad Autónoma de Buenos Aires"," Localidad: (*) "," Provincia (*): ")) | F20: =D5 | S20: San Luis
A21: Santa Rosa de Conlara | F21: San Luis | S21: Santa Cruz
A22: Instrumento verificado: | B22: Balanza para pesar camiones | J22: =IF(ISBLANK(B22),"",VLOOKUP(B22,$K$40:$O$51,5,FALSE)) | S22: Santa Fe
A23: Fabricante receptor: | B23: Balanza para pesar camiones | C23: Indicador: | D23: INDUSTRIAL SYSTEMS S.A. | E23: Tipo: | F23: electrónica | S23: Santiago del Estero
A24: Marca: Receptor: | B24: BIANCHETTI | E24: Indicador: | F24: BIANCHETTI | S24: Tierra de Fuego, Antártida e Islas del Atlántico Sur
A25: Modelo: Receptor: | B25: BASCULAS MAGNINO SRL | E25: Indicador: | F25: PB 10.000 | S25: Tucumán
A26: Nº serie: Receptor: | B26: 23032015172 | E26: Indicador: | F26: 23032015173
A27: Cód. ap. mod. Receptor: | B27: BASCULAS MAGNINO | E27: Indicador: | F27: SIPEL
A28: Origen Receptor | B28: MGF-3580G | E28: Indicador: | F28: ORION SPL 1A ALL | K28: III | L28: VERIFICACION PRIMITIVA | M28: electrónica | N28: 10 | O28: SI | P28: AUTOVERIFICACIÓN | Q28: VPR Nº:
A29: 1396 | D29: 80000 | E29: kg mín= | F29: 45319 | G29: kg | K29: IIII | L29: VERIFICACIÓN PERIÓDICA | M29: mecánica | N29: 20 | O29: NO | P29: VERIFICACIÓN PERIÓDICA | Q29: VPE Nº:
A30: e= | B30: BF.30-2147 | C30: =IF($F$23="Mecánica","kg d=dt=","kg dd=dt=") | D30: =IF(B30<>0,B30,"") | E30: kg clase= | F30: III | I30: =IF($F$23="Mecánica","d=dt=","dd=dt=") | L30: APROBACIÓN DE MODELO DE EFECTO LIMITADO | M30: híbrida | N30: 0.1 | P30: DECLARACIÓN DE CONFORMIDAD
A31: N° de Aprobación de Modelo: | B31: Argentina | E31: Indicador: | F31: Argentina | L31: PRIMITIVA DE INSTRUMENTO REPARADO A NUEVO | N31: 1 | P31: VERIFICACIÓN PRIMITIVA APROBACIÓN MODELO ÚNICO | Q31: VPR Nº:
A32: Fecha de Aprobación de Modelo: | B32: 8 de abril de 2010 | E32: Indicador: | F32: 20 de mayo de 1999
A33: Identidad del solicitante: (Razón social que solicita la OT y VPE) | B33: Acarayé S.A. | I33: Balancero 0 | J33: 123
A34: CUIT del solicitante: (Razón social que solicita la OT y VPE) | B34: =VLOOKUP($B$33,$I$33:$J$58,2,FALSE) | C34: MGF-3580G | H34: 20 | I34: Balancero 1 | J34: 456
A35: Situación legal del instrumento: | D35: 80000 | I35: EP Martinelli S.A.S. | J35: 3-071679479-9 | N35: 2 | P35: DECLARACIÓN CONFORMIDAD - AUTOVERIFICACIÓN
A36: Posee declaración de conformidad / certificado de autoverificación: | F36: NO | I36: Acarayé S.A. | J36: 30-70790202-3 | N36: 0.5 | P36: DECL. DE CONFORMIDAD / VER. PERIÓDICA
A37: 1000 | F37: III | I37: Básculas Guitart | J37: 34-50083873-3 | P37: VERIF. PRIM. INSTRUM. REPARADO A NUEVO
A38: Posee certificado de verificación periódica: | F38: NO | I38: Básculas Latorre S.A | J38: 30-50083873-2 | K38: III | L38: 50 | P38: VER. PRIM. AP. MOD. ÚNICO / VER. PERIÓDICA
A39: Se adjunta copia de alguno de los certificados: | F39: SI | I39: Básculas Casado S.R.L.. | J39: 30-71107332-5 | K39: IIII | L39: 10 | P39: VERIFICACIÓN PRIMITIVA
A40: De cual (número/s): | F40: BF.60-2219 | I40: S.P.I S.R.L.. | J40: 30-71487341-1 | K40: Balanza para pesar camiones | O40: 1
...

Sheet Datos de Ensayos
D1: METROLOGÍA LEGAL. VERIFICACIÓN DE BALANZAS
D2: Atencion: Llenar sólo las celdas grises. Para borrar el contenido de una celda usar la tecla "delete" o "supr", nunca la barra espaciadora. | AC2: VERIFICADOR | AD2: Documento | AE2: Carnet | AF2: Resolución N° | AG2: Datos de contacto
D3: Realizó | E3: Tco. Pablo Javier Siklosi A. | AB3: JO | AC3: Téc. Grottola Ruben | AD3: D.N.I. N° 29.332.227 | AE3: 145 | AF3: 346/09 | AG3: grottola@inti.gob.ar 1133556773
D4: Carga de datos | E4: Tco. Pablo Javier Siklosi A. | M4: Coloque sus datos en columnas AC hasta AF | AB4: GUIL | AC4: P.E. Oscar Alfredo GUILLÉN | AD4: D.N.I. N° 13.684.023 | AE4: 52 | AF4: 493/04 | AG4: oguillen@inti.gob.ar - TE 011-1533107309
AB5: AV | AC5: Tco. Juan Carlos Avagnina | AD5: D.N.I. N° 24.988.160 | AE5: 42 | AF5: 283/04 | AG5: avagnina@inti.gob.ar - TE 011-1566509752
D6: Informe Número: | E6: =IF(ISBLANK('Identificación del Instrumento'!B4),"",'Identificación del Instrumento'!B4) | I6: Fecha de verificación: | K6: ='Identificación del Instrumento'!J2 | AB6: SA | AC6: Tco. Cristian David SAKS | AD6: D.N.I. N° 31.134.998 | AE6: 212 | AF6: 493/04 | AG6: saks@inti.gob.ar - TE 011-1557294873
D7: Razón Social: | E7: =IF(ISBLANK('Identificación del Instrumento'!C14),"",'Identificación del Instrumento'!C14) | AB7: PA | AC7: Tco. Marcelo Alejandro PAGOT | AD7: D.N.I. N° 27.188.890 | AE7: 138 | AF7: 493/04 | AG7: mpagot@inti.gob.ar - TE 011-1557281013
D8: Lugar de instalación: | E8: =IF(ISBLANK('Identificación del Instrumento'!B15),"",+'Identificación del Instrumento'!B15) | AB8: BA | AC8: Tco. Marcelo Eduardo BAULIES | AD8: D.N.I. N° 25.921.560 | AE8: 59 | AF8: 268/05 | AG8: mbaulies@inti.gob.ar - TE 0351-158141793
D9: Localidad: | E9: =IF(ISBLANK('Identificación del Instrumento'!B16),"",'Identificación del Instrumento'!B16) | H9: Provincia: | I9: =IF(ISBLANK('Identificación del Instrumento'!F16),"",'Identificación del Instrumento'!F16) | AB9: LA | AC9: Ing. Enrique Daniel LAFON | AD9: D.N.I. N° 25.884.809 | AE9: 54 | AF9: 493/04 | AG9: elafon@inti.gob.ar - TE 011-1557272544
D10: Ubicación instrumento: | E10: =IF(ISBLANK('Identificación del Instrumento'!C18),"",CONCATENATE(+'Identificación del Instrumento'!C18,", ",'Identificación del Instrumento'!B19,", ",'Identificación del Instrumento'!B20,", ",'Identificación del Instrumento'!F20,"")) | AB10: FI | AC10: José Gabriel Figueroa | AD10: D.N.I. N° 24.982.875 | AE10: 56 | AF10: 493/04 | AG10: jfiguero@inti.gob.ar
D11: Fabricante: | E11: =IF(ISBLANK('Identificación del Instrumento'!B24),"",'Identificación del Instrumento'!B24) | H11: Indicador: | I11: =IF(ISBLANK('Identificación del Instrumento'!F24),"",'Identificación del Instrumento'!F24) | AB11: DE | AC11: Tco. Gabriel Hernán DENOT | AD11: D.N.I. N° 28.878.910 | AE11: 51 | AF11: 493/04 | AG11: gdenot@inti.gob.ar - TE 011-1557284370
D12: Modelo: | E12: =IF(ISBLANK('Identificación del Instrumento'!B25),"",'Identificación del Instrumento'!B25) | H12: Indicador: | I12: =IF(ISBLANK('Identificación del Instrumento'!F25),"",'Identificación del Instrumento'!F25) | AB12: CO | AC12: Tco. Pablo Daniel CORNET | AD12: D.N.I. N° 29.551.535 | AE12: 122 | AF12: 493/06 | AG12: pcornet@inti.gob.ar - TE 011-1557279865
D13: Nº de serie: | E13: =IF(ISBLANK('Identificación del Instrumento'!B26),"",'Identificación del Instrumento'!B26) | H13: Indicador: | I13: =IF(ISBLANK('Identificación del Instrumento'!F26),"",'Identificación del Instrumento'!F26) | AB13: RO | AC13: Ing. Mariela ROVERI | AD13: D.N.I. N° 25.381.092 | AE13: 160 | AF13: 493/04 | AG13: maroveri@inti.gob.ar - TE 011-1560378645
D14: Código de aprobación: | E14: =IF(ISBLANK('Identificación del Instrumento'!B27),"",'Identificación del Instrumento'!B27) | H14: Indicador: | I14: =IF(ISBLANK('Identificación del Instrumento'!F27),"",'Identificación del Instrumento'!F27) | L14: =VLOOKUP(I15,AE56:AF57,2,0) | M14: =L14 | AB14: RO | AC14: Tco. German Victor ALEKNAVISIUS | AD14: D.N.I. N° 22.205.335 | AE14: 97 | AF14: 493/04 | AG14: agerman@inti.gob.ar TE: 0341 152 132372
D15: Tipo de Verificación: | E15: =IF(ISBLANK('Identificación del Instrumento'!B17)," ",'Identificación del Instrumento'!B17) | H15: Tolerancia: | I15: =IF(ISBLANK('Identificación del Instrumento'!F17),"",'Identificación del Instrumento'!F17) | AB15: RO | AC15: Tco. Leonardo Leonel PIEDRABUENA | AD15: D.N.I. N° 31.339.312 | AE15: 280 | AF15: 493/04 | AG15: lpiedrabuena@inti.gob.ar TE: 0341 153695196
D16: Instrumento Verificado: | E16: =IF(ISBLANK('Identificación del Instrumento'!B22),"",'Identificación del Instrumento'!B22) | AB16: RO | AC16: Tco. Gonzalo Ignacio Arroyo | AD16: D.N.I. N° 35.051.221 | AE16: 240 | AF16: 493/04 | AG16: garroyo@inti.gob.ar TE: 0341 152297176
D17: Tipo de balanza: | E17: =IF(ISBLANK('Identificación del Instrumento'!F23),"",'Identificación del Instrumento'!F23) | I17: Clase: | J17: =IF(ISBLANK('Identificación del Instrumento'!F30),"",'Identificación del Instrumento'!F30) | AB17: RO | AC17: Tco. Damián Alberto QUEVEDO | AD17: D.N.I. N° 30.612.654 | AE17: 227 | AF17: 493/04 | AG17: dquevedo@inti.gob.ar - TE: 0341 155 967156
D18: Min Div (kg, e)= | E18: =IF(ISNUMBER('Identificación del Instrumento'!D30),'Identificación del Instrumento'!B30,"") | F18: d (kg)= | G18: =IF(ISBLANK('Identificación del Instrumento'!D30),"",'Identificación del Instrumento'!D30) | H18: Cap.Max (kg)= | I18: =IF(ISBLANK('Identificación del Instrumento'!D29),"",'Identificación del Instrumento'!D29) | AB18: RO | AC18: Tco. Ivan Alejandro PIASCIK | AD18: D.N.I. N° 31.182.999 | AE18: 233 | AF18: 493/04 | AG18: piascik@inti.gob.ar TE: 0342 154 731405
D19: Patrones (fabricante y modelo) | AB19: RO | AC19: Ing. Gastón Alexix ZANUTTI | AD19: D.N.I. N° 22.280.226 | AE19: 232 | AF19: 493/04 | AG19: gzanutti@inti.gob.ar TE: 0342 155 494338
D20: =IF(ISBLANK('Identificación del Instrumento'!A50),"",'Identificación del Instrumento'!A50) | AC20: Anl. Javier Leonardo Araujo | AD20: D.N.I. N° 21.618.342 | AE20: 430 | AF20: 364/15 | AG20: jaraujo@inti.gob.ar TE: 0379-154207685
AC21: Tco. Pablo Javier Siklosi A. | AD21: D.N.I. N° 24.705.518 | AE21: 96 | AF21: 519/05 | AG21: psiklosi@inti.gob.ar 2615774172
D22: Observaciones en general sobre la verificación, para incluir en el informe: | AC22: Otro Técnico | AD22: D.U. 49123456 | AE22: 007 | AF22: 20/25 | AG22: quednosayde@inti.gob.ar
H35: N° de apoyos: | K35: 10 | P35: 7 8 9 10 11 12
F36: indicador | P36: 6 5 4 3 2 1
K37: Escriba INDICADOR en la ubicación correspondiente
E38: =IF('Identificación del Instrumento'!B22="Balanza de plataforma","1",(IF(K35=12,CONCATENATE(P35,"",),IF(K35=10,CONCATENATE(P38,"",),IF(K35=8,CONCATENATE(P41,"",),IF(K35=6,CONCATENATE(P44,"",),IF(K35=4,CONCATENATE(P47,"",),""))))))) | P38: 6 7 8 9 10
D39: Egreso | E39: =IF('Identificación del Instrumento'!B22="Balanza de plataforma","3","") | F39: Receptor de Carga | I39: =IF('Identificación del Instrumento'!B22="Balanza de plataforma","4","") | J39: Ingreso | P39: 5 4 3 2 1
E41: =IF('Identificación del Instrumento'!B22="Balanza de plataforma","2",(IF(K35=12,CONCATENATE(P36,"",),IF(K35=10,CONCATENATE(P39,"",),IF(K35=8,CONCATENATE(P42,"",),IF(K35=6,CONCATENATE(P45,"",),IF(K35=4,CONCATENATE(P48,"",),""))))))) | P41: 5 6 7 8
P42: 4 3 2 1
P44: 4 5 6
P45: 3 2 1
D46: Clase de Instrumento | F46: Escalones
D47: I | E47: =IF(D47=J$17,"<====","") | F47: Hasta | H47: Error Máximo Tolerado | P47: 3 4
D48: II | E48: =IF(D48=J$17,"<====","") | F48: =IF(ISNUMBER(E51),IF(J17=D50,10*E51,IF(J17=D49,50*E51,IF(J17=D48,50*E51,IF(J17=D47,50*E51,"")))),"") | G48: kg | I48: ----------- | P48: 2 1
D49: III | E49: =IF(D49=J$17,"<====","") | F49: =IF(ISNUMBER(E51),MIN(IF(J17=D50,50*E51,IF(J17=D49,500*E51,IF(J17=D48,5000*E51,IF(J17=D47,50000*E51,"")))),I18),"") | G49: kg | H49: e = | I49: =IF(AND(ISNUMBER($E$51),ISNUMBER($L$14)),$E$51/$L$14,"") | J49: kg
D50: IIII | E50: =IF(D50=J$17,"<====","") | F50: =IF(ISNUMBER(E51),MIN(IF(J17=D50,200*E51,IF(J17=D49,2000*E51,IF(J17=D48,20000*E51,IF(J17=D47,200000*E51,"")))),I18),"") | G50: kg | H50: 2 e = | I50: =IF(AND(ISNUMBER(E51),ISNUMBER($L$14)),2*$E$51/$L$14,"") | J50: kg
D51: e = | E51: =E18 | F51: =IF(ISNUMBER(I18),I18,"") | G51: kg | H51: 3 e = | I51: =IF(AND(ISNUMBER(E51),ISNUMBER($L$14)),3*$E$51/$L$14,"") | J51: kg
H52: p
D54: 1 - VERIFICACIÓN DE LA INDICACIÓN DEL "CERO" DEL INSTRUMENTO (A.3.2.2. de la Resolución).
D55: El instrumento parte de cero: | F55: SI
...

Sheet Acta Verificación 
A1: #VALUE! | J1: =CONCATENATE("En la localidad de ",'Identificación del Instrumento'!$D$4,", provincia de ",'Identificación del Instrumento'!$D$5,", siendo las ",$J$18," horas del día ",'Identificación del Instrumento'!J2,", en virtud de la solicitud presentada por la firma ",'Identificación del Instrumento'!$C$14,", conforme a lo establecido en la Resolución Nº 611/2019 de la SECRETARÍA DE COMERCIO INTERIOR y sus modificatorias, el ",$T$18,", ",$T$19,", habilitado por el INSTITUTO NACIONAL DE TECNOLOGÍA INDUSTRIAL (I.N.T.I.), con credencial acreditante N° ",$T$20,", que en este acto se exhibe")
J2: =CONCATENATE(", en ejecución y en ejercicio de las facultades conferidas por la ley Nº 19.511,"&" el Decreto Reglamentario N° 960/2017, la Resolución Nº 611/2019 y sus modifiatorias, procede a hacerse presente en ",$J$24,"la firma citada, ubicada en ",$J$23,", siendo recibido por quien acredita ser ",$K$19,"; ",$J$20," Nº ",$K$20,", quien se desempeña en la firma como ",$J$22," y suscribe este instrumento en prueba de conformidad.")
J3: =CONCATENATE("A continuación se deja constancia que se verificó la concordancia con el modelo aprobado y se realizaron los ensayos de ",$N$44," respecto de los siguientes elementos: ",'Identificación del Instrumento'!$B$22," de tipo ",'Identificación del Instrumento'!$F$23,", compuesta por una plataforma receptora de cargas ",$N$30,"marca ",'Identificación del Instrumento'!$B$24,", modelo ",'Identificación del Instrumento'!$B$25,", N° de serie ",'Identificación del Instrumento'!$B$26,", código de aprobación de modelo ",'Identificación del Instrumento'!$B$27,", e indicador ",$P$30," de cargas marca ",'Identificación del Instrumento'!$F$24,", modelo ",'Identificación del Instrumento'!$F$25,", N° de serie ",'Identificación del Instrumento'!$F$26,", código de aprobación de modelo ",'Identificación del Instrumento'!$F$27,";")
J4: =CONCATENATE(" características metrológicas: capacidad máxima Máx.= ",'Identificación del Instrumento'!$D$29," kg; capacidad mínima Mín. = ",'Identificación del Instrumento'!$F$29," kg; e=dd=dt=",'Identificación del Instrumento'!$D$30," kg; clase ",'Identificación del Instrumento'!$F$30,", comprobando que los mismos cumplen con los requisitos de la verificación encomendada.")
J5: =CONCATENATE("Completada la presente verificación se cierra el acto, comprometiéndose el I.N.T.I. a emitir el ",$J$25,$J$26," en tiempo y forma, firmando como constancia el agente verificador y ",$J$19,"",$K$19," por la firma ",'Identificación del Instrumento'!$C$14,".")
J6: =CONCATENATE("Del presente se suscriben ",L30, " ejemplares de igual tenor, quedandosé uno en su poder ",$K$19," por la firma visitada.")
A14: =IF(ISBLANK('Identificación del Instrumento'!B17),"",CONCATENATE("ACTA DE ",'Identificación del Instrumento'!B17))
A16: =CONCATENATE("N° O.T.: ",'Identificación del Instrumento'!B4," ",'Identificación del Instrumento'!A5," ",'Identificación del Instrumento'!B5) | J16: Completar datos en celdas J18; K19; K20 y K21 | T16: DATOS DEL AGENTE VERIFICADOR | V16: TIPO DE DOCUMENTO RESPONSABLE
A18: =IF($J$29=6,CONCATENATE($J$1,$J$2),"¡Completar datos del acta!") | J18: 15:00 | M18: Hora de finalización de la tarea | S18: Nombre | T18: =+'Datos de Ensayos'!E4 | V18: D.N.I.
K19: Jaime Angel | M19: Responsable de la firma (QUIEN SE HACE CARGO) | S19: Tipo y Nº Doc. | T19: =VLOOKUP($T$18,'Datos de Ensayos'!$AC$3:$AG$21,2,0) | V19: L.E.
J20: D.N.I. | K20: 41819858 | M20: Tipo y Nº documento del Responsable | S20: Carnet Nº | T20: =VLOOKUP($T$18,'Datos de Ensayos'!$AC$3:$AG$21,3,0) | V20: L.C.
J21: e-mail - TE | K21: angeljaime809@gmail.com | M21: contacto del Responsable | V21: C.I.
J22: operario de báscula | M22: Cargo dentro de la firma | S22: Resolución habilitante | T22: =VLOOKUP($T$18,'Datos de Ensayos'!$AC$3:$AG$21,4,0) | V22: Pasaporte
J23: =IF(COUNTA('Identificación del Instrumento'!$B$19)=1,'Identificación del Instrumento'!$B$19,CONCATENATE('Identificación del Instrumento'!$B$15," de la localidad de ",'Identificación del Instrumento'!$B$16,", provincia de ",'Identificación del Instrumento'!$F$16)) | M23: Lugar de Ubicación del instrumento (automático)
J24: =IF(ISBLANK('Identificación del Instrumento'!$C$18),"",CONCATENATE('Identificación del Instrumento'!$C$18," de ")) | M24: Nombre específico del lugar del instrumento (automático) | V24: e-mail - TE
J25: =IF('Identificación del Instrumento'!$B$17="VERIFICACIÓN PERIÓDICA","informe")
J26: =IF('Identificación del Instrumento'!$B$17="VERIFICACIÓN PERIÓDICA"," previsto en la Resolución Nº 611/2019 de la SECRETARÍA DE COMERCIO INTERIOR y sus modificatorias",IF('Identificación del Instrumento'!$B$17="APROBACIÓN DE MODELO DE EFECTO LIMITADO"," previsto por el punto 2, Cap. II del Anexo I de la Resolución Nº 611/2019 de la SECRETARÍA DE COMERCIO INTERIOR"," previsto por el punto 3, Cap. II del Anexo I de la Resolución Nº 611/2019 de la SECRETARÍA DE COMERCIO INTERIOR"))
J27: =IF('Identificación del Instrumento'!$B$17="VERIFICACIÓN PERIÓDICA","1 del Cap. I y 1 del Cap. III",(IF('Identificación del Instrumento'!$B$17="APROBACIÓN DE MODELO DE EFECTO LIMITADO","1 del Cap. I y 2 del Cap. II","1 del Cap. I y 3 del Cap. II"))) | N27: TIPOS DE COMPONENTES DE LA BALANZA
J28: =IF('Identificación del Instrumento'!$B$17="VERIFICACIÓN PERIÓDICA","1 del Cap. III del Anexo I",(IF('Identificación del Instrumento'!$B$17="APROBACIÓN DE MODELO DE EFECTO LIMITADO","2 del Cap. II del Anexo I","3 del Cap. II del Anexo I")))
J29: =COUNTIF(K29:K34,"=FALSO") | K29: =ISBLANK(J18) | L29: =IF('Identificación del Instrumento'!$B$17="VERIFICACIÓN PERIÓDICA","b)","a)") | N29: PLATAFORMA | P29: INDICADOR
K30: =ISBLANK(K19) | L30: =IF('Identificación del Instrumento'!$B$17="VERIFICACIÓN PERIÓDICA","dos (2)","tres (3)") | N30: =IF('Identificación del Instrumento'!$F$23="electrónica","","tipo mecánica ") | P30: =IF(ISBLANK('Identificación del Instrumento'!$F$23),"",IF('Identificación del Instrumento'!$F$23="mecánica","mecánico","electrónico"))
A31: =IF(COUNTBLANK(Informe!$F$20:$F$25)=6,CONCATENATE($J$3,$J$4),"¡LA BALANZA NO CUMPLE!") | K31: =ISBLANK(K20)
K32: =ISBLANK(J22)
K33: =AND(ISBLANK('Identificación del Instrumento'!$B$19),ISBLANK('Identificación del Instrumento'!$B$15),ISBLANK('Identificación del Instrumento'!$B$16),ISBLANK('Identificación del Instrumento'!$F$16))
K34: =ISBLANK(J24)
N37: ENSAYOS EFECTUADOS
N38: =IF(Informe!$G$23=Informe!$J$2,""," fidelidad")
N39: =IF(Informe!$G$22=Informe!$J$2,"",", excentricidad")
A40: =IF($J$29=6,J5,"¡Completar datos del acta!") | N40: =IF(Informe!$G$24=Informe!$J$2,"",", movilidad")
N41: =IF(Informe!$G$20=Informe!$J$2,"",IF(AND(N42="",N43="")," y errores de indicación",", errores de indicación"))
N42: =IF(Informe!$G$21=Informe!$J$2,"",", desvíos entre resultados")
N43: =IF(Informe!$G$25=Informe!$J$2,""," y efecto máximo del dispositivo de puesta a cero")
A44: =IF($J$29=6,J6,"¡Completar datos del acta!") | N44: =CONCATENATE($N$38,$N$39,$N$40,$N$41,$N$42,$N$43)
A57: =+K19 | F57: =+T18
A58: =+'Identificación del Instrumento'!C14 | F58: Programa de Metrología Legal - INTI
A59: =K21

Sheet Acta Precintos
A10: ACTA DE PRECINTADO
K11: En las Balanzas tipo Electronicas se debe precintar en:
A13: Fecha: | B13: =IF(ISBLANK('Identificación del Instrumento'!J2),"",'Identificación del Instrumento'!J2) | K13: Cabezal electrónico
A14: Objeto: | B14: =IF(ISBLANK('Identificación del Instrumento'!B22)," ",'Identificación del Instrumento'!B22) | K14: Cajas de ecualización
A15: Fabricante / Importador: | C15: Receptor: | D15: =IF(ISBLANK('Identificación del Instrumento'!B24),"",'Identificación del Instrumento'!B24) | F15: Indicador: | G15: =IF(ISBLANK('Identificación del Instrumento'!F24),"",'Identificación del Instrumento'!F24) | K15: Celdas de carga
A16: Modelo: | C16: Receptor: | D16: =IF(ISBLANK('Identificación del Instrumento'!B25),"",'Identificación del Instrumento'!B25) | F16: Indicador: | G16: =IF(ISBLANK('Identificación del Instrumento'!F25),"",'Identificación del Instrumento'!F25) | K16: Cableado
A17: Número de Serie: | C17: Receptor: | D17: =IF(ISBLANK('Identificación del Instrumento'!B26),"",'Identificación del Instrumento'!B26) | F17: Indicador: | G17: =IF(ISBLANK('Identificación del Instrumento'!F26),"",'Identificación del Instrumento'!F26)
A18: Cód. de aprob. de modelo: | C18: Receptor: | D18: =IF(ISBLANK('Identificación del Instrumento'!B27),"",'Identificación del Instrumento'!B27) | F18: Indicador: | G18: =IF(ISBLANK('Identificación del Instrumento'!F27),"",'Identificación del Instrumento'!F27)
A19: Propietario o Permisionario: | C19: =IF(ISBLANK('Identificación del Instrumento'!C14),"",'Identificación del Instrumento'!C14)
A20: ='Acta Verificación '!A16:F16
K21: En las Balanzas tipo Híbridas se debe precintar en:
B22: =IF(ISBLANK('Identificación del Instrumento'!F23)," ",CONCATENATE("Balanza ",'Identificación del Instrumento'!F23)) | K22: Contrapeso de cero
B23: Ubicación | E23: Nº Precinto / Tipo (1) | K23: Contrapeso móvil del brazo
B24: Placa identificatoria | C24: del receptor | E24: (a) I18850 | K24: Tapa columna contra leva | Q24: =IF(ISBLANK(F24),"",F24) | S24: =IF(ISBLANK(E24),"",IF(ISBLANK(E25),CONCATENATE("",B24," ",C24, " ",E24),CONCATENATE("",B24," ",C24," ",E24)))
C25: del indicador | E25: (a) K26189 | K25: Levas | S25: =IF(ISBLANK(E25),"",IF(ISBLANK(E26),CONCATENATE(" y ",B24," ",C25," ",E25),CONCATENATE(", ",B24," ",C25," ",E25)))
B26: Indicador | E26: (a) B 79079, B 79080 (07/10/25) | K26: Barras de mando | S26: =IF(ISBLANK(E26),"",IF(ISBLANK(E27),CONCATENATE(", ",B26, " ",E26),CONCATENATE(", ",B26," ",E26)))
B27: Caja de ecualización | E27: (a) B 79081, B 79082 (07/10/25) | K27: Barra de transmisión | S27: =IF(ISBLANK(E27),"",IF(ISBLANK(E28),CONCATENATE(", ",B27, " ",E27),CONCATENATE(", ",B27," ",E27)))
B28: Cable de celda | E28: (a) 2143932 | K28: Entrada de hombre a fosa | S28: =IF(ISBLANK(E28),"",IF(ISBLANK(E29),CONCATENATE(" y ",B28, " ",E28),CONCATENATE(", ",B28," ",E28)))
B29: Verificado | E29: (a) 1036542 (07/10/25) | S29: =IF(ISBLANK(E29),"",IF(ISBLANK(E30),CONCATENATE(" y ",B29, " ",E29),CONCATENATE(", ",B29," ",E29)))
S30: =IF(ISBLANK(E30),"",IF(ISBLANK(E31),CONCATENATE(" y ",B30, " ",E30),CONCATENATE(", ",B30," ",E30)))
K31: Cabezal electrónico | S31: =IF(ISBLANK(E31),"",IF(ISBLANK(E32),CONCATENATE(" y ",B31, " ",E31),CONCATENATE(", ",B31," ",E31)))
K32: Celda de carga | S32: =IF(ISBLANK(E32),"",IF(ISBLANK(E33),CONCATENATE(" y ",B32, " ",E32),CONCATENATE(", ",B32," ",E32)))
K33: Cableado | S33: =IF(ISBLANK(E33),"",IF(ISBLANK(E34),CONCATENATE(" y ",B33, " ",E33),CONCATENATE(", ",B33," ",E33)))
S34: =IF(ISBLANK(E34),"",IF(ISBLANK(E35),CONCATENATE(" y ",B34, " ",E34),CONCATENATE(", ",B34," ",E34)))
S35: =IF(ISBLANK(E35),"",IF(ISBLANK(E36),CONCATENATE(" y ",B35, " ",E35),CONCATENATE(", ",B35," ",E35)))
S36: =IF(ISBLANK(E36),"",IF(ISBLANK(E37),CONCATENATE(" y ",B36, " ",E36),CONCATENATE(", ",B36," ",E36)))
S37: =IF(ISBLANK(E37),"",IF(ISBLANK(E38),CONCATENATE(" y ",B37, " ",E37),CONCATENATE(", ",B37," ",E37)))
S38: =IF(ISBLANK(E38),"",IF(ISBLANK(E39),CONCATENATE(" y ",B38, " ",E38),CONCATENATE(", ",B38," ",E38)))
S39: =IF(ISBLANK(E39),"",IF(ISBLANK(E40),CONCATENATE(" y ",B39, " ",E39),CONCATENATE(", ",B39," ",E39)))
S40: =IF(ISBLANK(E40),"",IF(ISBLANK(E41),CONCATENATE(" y ",B40, " ",E40),CONCATENATE(", ",B40," ",E40)))
S41: =IF(ISBLANK(E41),"",IF(ISBLANK(E42),CONCATENATE(" y ",B41, " ",E41),CONCATENATE(", ",B41," ",E41)))
S42: =IF(ISBLANK(E42),"",IF(ISBLANK(E43),CONCATENATE(" y ",B42, " ",E42),CONCATENATE(", ",B42," ",E42)))
S43: =IF(ISBLANK(E43),"",IF(ISBLANK(E44),CONCATENATE(" y ",B43, " ",E43),CONCATENATE(", ",B43," ",E43)))
S44: =IF(ISBLANK(E44),"",IF(ISBLANK(E45),CONCATENATE(" y ",B44, " ",E44),CONCATENATE(", ",B44," ",E44)))
S45: =IF(ISBLANK(E45),"",IF(ISBLANK(E46),CONCATENATE(" y ",B45, " ",E45),CONCATENATE(", ",B45," ",E45)))
S46: =IF(ISBLANK(E46),"",IF(ISBLANK(E47),CONCATENATE(" y ",B46, " ",E46),CONCATENATE(", ",B46," ",E46)))
S47: =IF(ISBLANK(E47),"",IF(ISBLANK(E49),CONCATENATE(" y ",B47, " ",E47),CONCATENATE(", ",B47," ",E47)))
A49: Los precintos sólo se pueden romper ante la presencia del INTI o por reparador auditado de acuerdo a lo establecido en la Resolución 611-2019 y sus modificatorias. | K49: En las Balanzas tipo Mecánicas se debe precintar en: | S49: =CONCATENATE(S24,S25,S26,S27,S28,S29,S30,S31,S32,S33,S34,S35,S36,S37,S38,S39,S40,S41,S42,S43,S44,S45,S46,S47)
A51: Listado de reparadores auditados: | K51: Contrapeso de cero
A52: https://www.inti.gob.ar/areas/metrologia-y-calidad/metrologia/metrologia-legal/empresas-reparadoras-auditadas | K52: Contrapeso móvil del brazo
...

Sheet Informe
A1: Revisó - aprobó: | C1: =CONCATENATE('Datos de Ensayos'!E3," - ",'Datos de Ensayos'!E4)
J2: Ö
A4: =IF(('Identificación del Instrumento'!B17)="VERIFICACIÓN PERIÓDICA",CONCATENATE("INFORME DE ",'Identificación del Instrumento'!B17),CONCATENATE("INFORME DE ENSAYO"))
A5: =CONCATENATE("N° O.T.: ",'Identificación del Instrumento'!B4) | I5: =IF(ISBLANK('Datos de Ensayos'!E6),"Falta No.parcial","") | N5: MARGENES DE CERTIFICADO
A6: =IF(OR(ISBLANK('Identificación del Instrumento'!B22),ISBLANK('Identificación del Instrumento'!D29),ISBLANK('Identificación del Instrumento'!D30),ISBLANK('Identificación del Instrumento'!F30)),"",CONCATENATE("Instrumento: ",'Identificación del Instrumento'!B22,", de capacidad máxima ",'Datos de Ensayos'!I18," kg,"," mínima división ",'Datos de Ensayos'!E18," kg, clase ",'Datos de Ensayos'!J17,", de tipo ",'Datos de Ensayos'!E17,".")) | P6: SUP 6,0 | S6: ENCAB 6,0
A7: =CONCATENATE("Fabricante / importador: ",IF(AND('Identificación del Instrumento'!B23<>"",'Identificación del Instrumento'!F23<>"",'Identificación del Instrumento'!B23<>'Identificación del Instrumento'!F23),CONCATENATE(," Receptor: ",'Identificación del Instrumento'!B23," / Indicador: ",'Identificación del Instrumento'!D23),IF('Identificación del Instrumento'!B23='Identificación del Instrumento'!F23,'Identificación del Instrumento'!B23,""))) | N7: IZQ 1,0 | R7: DER 1,0
A8: =CONCATENATE("Marca: ",IF(AND('Identificación del Instrumento'!B24<>"",'Identificación del Instrumento'!F24<>"",'Identificación del Instrumento'!B24<>'Identificación del Instrumento'!F24),CONCATENATE(," Receptor: ",'Identificación del Instrumento'!B24," / Indicador: ",'Identificación del Instrumento'!F24),IF('Identificación del Instrumento'!B24='Identificación del Instrumento'!F24,'Identificación del Instrumento'!B24,"")))
A9: =CONCATENATE("Modelo: ",IF(AND('Identificación del Instrumento'!B25<>"",'Identificación del Instrumento'!F25<>"",'Identificación del Instrumento'!B25<>'Identificación del Instrumento'!F25),CONCATENATE(," Receptor: ",'Identificación del Instrumento'!B25," / Indicador: ",'Identificación del Instrumento'!F25),IF('Identificación del Instrumento'!B25='Identificación del Instrumento'!F25,'Identificación del Instrumento'!B25,"")))
A10: =CONCATENATE("Número de serie: ",IF(AND('Identificación del Instrumento'!B26<>"",'Identificación del Instrumento'!F26<>"",'Identificación del Instrumento'!B26<>'Identificación del Instrumento'!F26),CONCATENATE(," Receptor: ",'Identificación del Instrumento'!B26," / Indicador: ",'Identificación del Instrumento'!F26),IF('Identificación del Instrumento'!B26='Identificación del Instrumento'!F26,'Identificación del Instrumento'!B26,""))) | I10: =IF(ISBLANK('Datos de Ensayos'!E14),"Falta No. serie","")
A11: =CONCATENATE("Origen: ",IF(AND('Identificación del Instrumento'!B28<>"",'Identificación del Instrumento'!F28<>"",'Identificación del Instrumento'!B28<>'Identificación del Instrumento'!F28),CONCATENATE(," Receptor: ",'Identificación del Instrumento'!B28," / Indicador: ",'Identificación del Instrumento'!F28),IF('Identificación del Instrumento'!B28='Identificación del Instrumento'!F28,'Identificación del Instrumento'!B28,"")))
A12: =CONCATENATE("N° de Aprobación de Modelo: ",IF(AND('Identificación del Instrumento'!B31<>"",'Identificación del Instrumento'!F31<>"",'Identificación del Instrumento'!B28<>'Identificación del Instrumento'!F31),CONCATENATE(," Receptor: ",'Identificación del Instrumento'!B31," / Indicador: ",'Identificación del Instrumento'!F31),IF('Identificación del Instrumento'!B31='Identificación del Instrumento'!F31,'Identificación del Instrumento'!B31,"")))
A13: =CONCATENATE("Fecha de Aprobación de Modelo: ",IF(AND('Identificación del Instrumento'!B32<>"",'Identificación del Instrumento'!F32<>"",'Identificación del Instrumento'!B29<>'Identificación del Instrumento'!F32),CONCATENATE(," Receptor: ",'Identificación del Instrumento'!B32," / Indicador: ",'Identificación del Instrumento'!F32),IF('Identificación del Instrumento'!B32='Identificación del Instrumento'!F32,'Identificación del Instrumento'!B32,"")))
A14: =CONCATENATE("Código de aprobación de modelo: ",IF(AND('Identificación del Instrumento'!B27<>"",'Identificación del Instrumento'!F27<>"",'Identificación del Instrumento'!B27<>'Identificación del Instrumento'!F27),CONCATENATE("Receptor "," ", 'Identificación del Instrumento'!B27," / Indicador ",'Identificación del Instrumento'!F27),IF('Identificación del Instrumento'!B27='Identificación del Instrumento'!F27,'Identificación del Instrumento'!B27,""))) | I14: =IF(ISBLANK('Datos de Ensayos'!E14),"Falta identificacion","") | P14: INF 6,0 | S14: PIE 6,0
A15: =CONCATENATE("Precintos Nº: ",'Acta Precintos'!S49,".") | I15: =IF(ISBLANK('Datos de Ensayos'!E8),"Falta Razón social","") | N15: ESCALA 80%
A16: =IF((AND(ISBLANK('Identificación del Instrumento'!B19),ISBLANK('Identificación del Instrumento'!F20))),CONCATENATE("Lugar de instalacion: ",IF('Identificación del Instrumento'!F16="Ciudad Autónoma de Buenos Aires",('Identificación del Instrumento'!B15&" de la "&'Identificación del Instrumento'!F16&"."),('Identificación del Instrumento'!B15&" de la localidad de "&'Identificación del Instrumento'!B16&", provincia de "&'Identificación del Instrumento'!F16&"."))), CONCATENATE("Lugar de instalación: ",IF(ISBLANK('Identificación del Instrumento'!C18),"",'Identificación del Instrumento'!C18&" - "),IF('Identificación del Instrumento'!F20="Ciudad Autónoma de Buenos Aires",('Identificación del Instrumento'!B19&" de la "&'Identificación del Instrumento'!F20&"."),('Identificación del Instrumento'!B19&" de la localidad de "&'Identificación del Instrumento'!B20&", provincia de "&'Identificación del Instrumento'!F20&"."))))
A17: Determinación requerida: | C17: =IF(COUNTA('Identificación del Instrumento'!$B$22)=1,VLOOKUP('Identificación del Instrumento'!$J$22,Informe!$I$17:$J$18,2,FALSE),"") | I17: 1 | J17: Verificación del cumplimiento con la Reglamentación Metrológica y Técnica correspondiente a la Resolución ex S.E.C. y N.E.I. N° 2307/1980 y su modificatoria. | U17: Párrafos de la Reglamentación Metrológica y Técnica, Resolución 2307/80
A18: Conclusión: En la tabla siguiente figuran las verificaciones efectuadas y las conclusiones obtenidas. | I18: 2 | J18: Verificación del cumplimiento con las Reglamentaciones Metrológica y Técnica correspondientes a las Resoluciones S.C.D. y D.C. N° 119/2001, ex S.E.C. y N.E.I. N° 2307/1980 y su modificatoria . | U18: Párrafos de las Reglamentaciones Metrológica y Técnica, Resoluciones 2307/80 y 119/2001 (*)
A19: =IF(COUNTA('Identificación del Instrumento'!$B$22)=1,VLOOKUP('Identificación del Instrumento'!$J$22,$I$17:$V$18,13,FALSE),"") | D19: Satisface | F19: No satisface | G19: No aplicable
A20: 9 | B20: Errores de indicación | D20: =J2
A21: 11.1.1 | B21: Desvíos entre resultados | G21: =+J2
A22: =IF('Identificación del Instrumento'!B22="Balanza tipo tolva","ESCONDER",(IF(COUNTA('Identificación del Instrumento'!$B$22)=1,VLOOKUP('Identificación del Instrumento'!$B$22,'Ensayos Efectuados'!$N$125:$R$136,5,FALSE),""))) | B22: =IF(OR(A22="ESCONDER",A22="N/A"),"ESCONDER","Excentricidad") | D22: =IF($B$22="ESCONDER","ESCONDER",IF(COUNT('Datos de Ensayos'!K70:K81)>1,IF('Datos de Ensayos'!K82=0,J2,""),"")) | F22: =IF($B$22="ESCONDER","",IF('Datos de Ensayos'!K82>0,J2,"")) | G22: =IF($B$22="ESCONDER","ESCONDER"," ") | I22: =IF(OR('Identificación del Instrumento'!B22="Balanza tipo tolva",'Identificación del Instrumento'!B22="Balanza de carga directamente suspendida (de gancho)"),"<=== Esconder fila 'Excentricidad' "," ")
A23: 14.1.2. | B23: Fidelidad | D23: =IF(ISNUMBER('Datos de Ensayos'!$N$135),IF(('Datos de Ensayos'!$N$135=0),J2,""),"") | F23: =IF(ISNUMBER('Datos de Ensayos'!$N$135),IF(('Datos de Ensayos'!$N$135=1),J2,""),J2)
A24: =IF('Identificación del Instrumento'!F23="Mecánica","14.2.1.1.","14.2.2.1.2.") | B24: Movilidad | D24: =+IF(AND(COUNTA('Datos de Ensayos'!E61:E63)=3,'Datos de Ensayos'!K61="si",'Datos de Ensayos'!K62="si",'Datos de Ensayos'!K63="si"),J2,"") | F24: =+IF(OR(COUNTA('Datos de Ensayos'!E61:E63)<3,'Datos de Ensayos'!K61="no",'Datos de Ensayos'!K62="no",'Datos de Ensayos'!K63="no"),J2,"")
A25: A.3.2.2. | B25: Efecto máximo del dispositivo de puesta a cero | D25: =+IF('Datos de Ensayos'!G56="no supera",$J$2,"") | F25: =+IF('Datos de Ensayos'!G56="supera",J2,"") | G25: =+IF('Datos de Ensayos'!G56="x",J2,"")
A26: Evaluación de la concordancia con el modelo aprobado | D26: =$J$2 | F26: =+IF('Datos de Ensayos'!G57="supera",J3,"") | G26: =+IF('Datos de Ensayos'!G57="x",J3,"")
A27: =IF(COUNTBLANK(F20:F25)=6,"La balanza satisface los requisitos reglamentarios.","La balanza no satisface los requisitos reglamentarios.")
A28: =CONCATENATE("Fecha de la verificación: ") | D28: ='Identificación del Instrumento'!J2
A29: =CONCATENATE("Fecha de emisión: ") | D29: =TODAY()
A30: =CONCATENATE("Fecha de vencimiento: ") | D30: ='Identificación del Instrumento'!J3
A31: Los registros de verificación se encuentran archivados en el INTI.
A32: Las mediciones involucradas en este informe están vinculadas a los patrones de medida mantenidos en el INTI según la legislación vigente, los cuales representan a las unidades físicas de medida en concordancia con el Sistema Internacional de Unidades (SI).
A33: Usuario: | B33: =IF(ISBLANK('Identificación del Instrumento'!$C$14),"",'Identificación del Instrumento'!$C$14)
B34: =IF(ISBLANK('Identificación del Instrumento'!$B$15),"",'Identificación del Instrumento'!$B$15)
B35: =CONCATENATE('Datos de Ensayos'!$E$9,IF('Identificación del Instrumento'!F16="Ciudad Autónoma de Buenos Aires",""," - Provincia de "),'Datos de Ensayos'!$I$9)
A79: Excentricidad:
B80: ='Datos de Ensayos'!F82 | C80: ='Datos de Ensayos'!F68 | E80: ='Datos de Ensayos'!#REF! | H80: 2
A81: Se utilizó una carga aproximada de
B82: =TEXT('Datos de Ensayos'!E68,"0") | C82: ='Datos de Ensayos'!F68 | E82: =+'Datos de Ensayos'!H112
A85: =IF(#REF!=0,"El instrumento cumple con las tolerancias establecidas en el punto 9.1.1. de la Resolución 2307 de la Secretaría de Comercio ","El instrumento no cumple con las tolerancias establecidas en el punto 9.1.1. de la Resolución 2307 de la Secretaría de Comercio")
A89: Los valores de incertidumbre de medición que aparecen en la tabla de errores de indicación fueron calculados combinando la incertidumbre de las pesas patrones, y los componentes asociados a la fidelidad y resolución de la balanza. La incertidumbre standard asociada a las combinaciones de pesas patrones utilizadas resultó siempre menor que
...

Sheet Reporte
A1: Identificacion del solicitante | B1: C.U.I.T. del solicitante | C1: Número de Certificado | D1: Denominacion del instrumento | E1: Marca | F1: Modelo | G1: Origen | H1: Numero de serie | I1: Ubicación del instrumento (solo para instrumentos de instalacion fija) | J1: Fecha de emision del certificado | K1: Laboratorio interviniente | L1: Numero de informe de ensayo emitido por el laboratorio interviniente
A2: ='Identificación del Instrumento'!B33 | B2: ='Identificación del Instrumento'!B34 | C2: Para completar por OC | D2: =+Informe!A6 | E2: =Informe!A8 | F2: =Informe!A9 | G2: =Informe!A11 | H2: =Informe!A10 | I2: =Informe!A16 | J2: Para completar por OC | K2: INTI DT de METROLOGIA LEGAL | L2: =+Informe!A5

Sheet certificado OC
F1: Fecha de emisión: | H1: =TODAY()
F2: Fecha de vencimiento: | H2: =+Informe!D30
A8: CERTIFICADO DE VERIFICACION PERIODICA N° ML-VPE-301-INTI-2307/80-0001
A12: =CONCATENATE( "En virtud de la presentación realizada por la firma ", 'Identificación del Instrumento'!B33, ", C.U.I.T. Nº ", 'Identificación del Instrumento'!B34, " habiéndose analizado los antecedentes y considerando que se han cumplido con los requisitos establecidos, se certifica que el instrumento presentado a la Verificación periódica, reúne los requisitos establecidos en la Resolución ex - S. C. I. Nº 611/2019", " y sus modificatorias y cumple con las especificaciones y tolerancias establecidas en el Reglamento Técnico y Metrológico Aplicable, según los “Informes de Ensayos” correspondiente a los Números:", 'Identificación del Instrumento'!B4, ", emitido por el laboratorio INTI -DT Metrología Legal " )
A14: =+Informe!A7
A15: =+Informe!A6
A16: =Informe!A8
A17: =+Informe!A9
A18: =+Informe!A10
A19: =Informe!A11
A20: Cantidad: 1
A21: Características metrológicas:
B22: Máx.: | C22: ='Identificación del Instrumento'!D29
B23: Mín.: | C23: ='Identificación del Instrumento'!F29
B24: e:dd: | C24: ='Identificación del Instrumento'!B30
B25: Clase | C25: ='Identificación del Instrumento'!F30
A26: =Informe!A16
A27: Responsable: | B27: =+Informe!B33
A28: Reglamento Metrologico aplicable: | B28: Resolución de la ex-SECYNEI Nº 2307/1980 y su modificatoria.
A29: Fecha de finalizacion de los ensayos: | B29: =Informe!D28
A30: =Informe!A14
A31: =Informe!A12
A32: =Informe!A13
A33: Fecha de aprobacion de variante: | B33: No aplica
A34: Nro. aprobacion de variante de modelo: | B34: No aplica
A35: Fecha de aprobacion de variante de modelo: | B35: No aplica
A36: Numero de precintos: | B36: =+Informe!A15
A37: Resultado de la verificacion periodica | B37: El instrumento satisface los requisitos reglamentarios
A38: Nota: Orden de trabajo OC
H41: Fin del certificado
A50: =IF(OR(ISBLANK('Identificación del Instrumento'!B22),ISBLANK('Identificación del Instrumento'!D29),ISBLANK('Identificación del Instrumento'!D30),ISBLANK('Identificación del Instrumento'!F30)),"",CONCATENATE("Características metrológicas: Máx.: ",'Datos de Ensayos'!I18," kg,"," e:dd: ",'Datos de Ensayos'!E18," kg, clase: ",'Datos de Ensayos'!J17,""))

Sheet Acta Suspensión
N3: =CONCATENATE("En la localidad de ",'Identificación del Instrumento'!$D$4,", provincia de ",'Identificación del Instrumento'!$D$5,", siendo las ",$J$18," horas del día ",TEXT('Identificación del Instrumento'!J2,"d/mm/yyyy"),", en virtud de la solicitud y declaración jurada presentada por la firma ",'Identificación del Instrumento'!$C$14,", conforme el punto ",$J$27," de la Resolución Nº 611/2019 de la SECRETARÍA DE COMERCIO INTERIOR, el ",$T$18,", ",$T$19,", habilitado por el INSTITUTO NACIONAL DE TECNOLOGÍA INDUSTRIAL (I.N.T.I.), con credencial acreditante N° ",$T$20,", que en este acto se exhibe")
N4: =CONCATENATE(", en ejecución y en ejercicio de las facultades conferidas por la ley Nº 19.511, "&" el inciso l) del Artículo 2 del Decreto Reglamentario N° 960/2017, el inciso ",L28, " del Artículo 1 de la Resolución E 8/2018 del 10 de enero del 2018 de la Secretaría de Comercio y los puntos ",$J$26," ambos del Anexo I la citada Resolución Nº 611/2019, procede a hacerse presente en ",$J$23,"la firma citada, ubicada en ",$J$22,", siendo recibido por quien acredita ser ",$K$19,", ",$J$20," Nº ",$K$20,", quien se desempeña en la firma como ",$J$21," y suscribe este instrumento en prueba de conformidad.")
N5: =CONCATENATE("A continuación se deja constancia que la ",'Identificación del Instrumento'!B17," respecto de los siguientes elementos: ",'Identificación del Instrumento'!$B$22," de tipo ",'Identificación del Instrumento'!$F$23,", compuesta por una plataforma receptora de cargas ",$N$29,"marca ",'Identificación del Instrumento'!$B$24,", modelo ",'Identificación del Instrumento'!$B$25,", N° de serie ",'Identificación del Instrumento'!$B$26,", código de aprobación de modelo ",'Identificación del Instrumento'!$B$27,", e indicador ",$P$29," de cargas marca ",'Identificación del Instrumento'!$F$24,", modelo ",'Identificación del Instrumento'!$F$25,", N° de serie ",'Identificación del Instrumento'!$F$26,", código de aprobación de modelo ",'Identificación del Instrumento'!$F$27,";")
N6: =CONCATENATE(" características metrológicas: capacidad máxima Máx.= ",'Identificación del Instrumento'!$D$29," kg; capacidad mínima Mín. = ",'Identificación del Instrumento'!$F$29," kg; e=dd=dt=",'Identificación del Instrumento'!$D$30," kg; clase ",'Identificación del Instrumento'!$F$30,", prevista para el día de la fecha, se suspende por el siguiente motivo: ",'Informe Suspensión'!J16,".")
N7: =CONCATENATE("Sin más, se cierra el acto firmando como constancia el agente verificador y ",$K$19," por la firma ",'Identificación del Instrumento'!$C$14,".")
N8: =CONCATENATE("Del presente se suscriben dos ejemplares de igual tenor, quedando uno en poder de ",$K$19," por la firma visitada.")
J10: ¿Porqué se suspendió?: | L10: Errores de indicación
A14: =IF('Acta Verificación '!A31="¡LA BALANZA NO CUMPLE!"," ACTA ","NO IMPRIMIR")
AB15: Efecto máximo del dispositivo de puesta a cero | AC15: =CONCATENATE("NO CUMPLE con el ",AD15, " ",AE15) | AD15: punto A.3.2.2 de la Resolución S.C. y N.E.I. Nº 2307/80 | AE15: (Efecto máximo del dispositivo de puesta a cero).
A16: =CONCATENATE("O.T. Nº: ",'Identificación del Instrumento'!B4," ",'Identificación del Instrumento'!A5," ",'Identificación del Instrumento'!B5) | J16: Completar datos en celdas J18; K19; K20 y K21 | S16: Los datos del verificador vienen de la hoja Datos de Ensayo celdas E3 y AC4 hasta AF36 respectivamente | V16: TIPO DE DOCUMENTO RESPONSABLE | AB16: Errores de indicación | AC16: =CONCATENATE("NO CUMPLE con el ",AD16, " ",AE16) | AD16: punto 9.1.1 de la Resolución S.C. y N.E.I. Nº 2307/80 | AE16: (Errores de indicación)
AB17: Fidelidad | AC17: =CONCATENATE("NO CUMPLE con el ",AD17, " ",AE17) | AD17: punto 14.1.2 de la Resolución S.C. y N.E.I. Nº 2307/80 | AE17: (Fidelidad).
A18: =IF($J$28=6,CONCATENATE($N$3,$N$4),"¡Completar datos del acta!") | J18: 15:00 | M18: Hora de finalización de la tarea | S18: Nombre | T18: =IF(COUNTA('Datos de Ensayos'!$E$4)=1,'Datos de Ensayos'!$E$4,"") | V18: D.N.I. | W18: Sr. | AB18: Movilidad (balanza mecánica de eq. no automático) | AC18: =CONCATENATE("NO CUMPLE con el ",AD18, " ",AE18) | AD18: punto 14.2.1.1 de la Resolución S.C. y N.E.I. Nº 2307/80 | AE18: (Movilidad).
K19: ='Acta Verificación '!K19:L19 | M19: Responsable de la firma (QUIEN SE HACE CARGO) | S19: Tipo y Nº Doc. | T19: =IF($T$18<>"",VLOOKUP($T$18,'Datos de Ensayos'!$AC$3:$AF$34,2,FALSE),"") | V19: L.E. | W19: Sra. | AB19: Movilidad (balanza mecánica de eq. automático indicación contínua) | AC19: =CONCATENATE("NO CUMPLE con el ",AD19, " ",AE19) | AD19: punto 14.2.2.1.1 de la Resolución S.C. y N.E.I. Nº 2307/80 | AE19: (Movilidad).
J20: D.N.I. | K20: ='Acta Verificación '!K20:L20 | M20: Tipo y Nº documento del Responsable | S20: Carnet Nº | T20: =IF($T$18<>"",VLOOKUP($T$18,'Datos de Ensayos'!$AC$3:$AF$34,3,FALSE),"") | V20: L.C. | W20: Srta. | AB20: Movilidad (balanza mecánica de eq. Automático indicación discontínua) | AC20: =CONCATENATE("NO CUMPLE con el ",AD20, " ",AE20) | AD20: punto 14.2.2.1.2 de la Resolución S.C. y N.E.I. Nº 2307/80 | AE20: (Movilidad).
J21: ='Acta Verificación '!J22:L22 | M21: Cargo dentro de la firma | S21: Res habilitante | T21: =IF($T$18<>"",VLOOKUP($T$18,'Datos de Ensayos'!$AC$3:$AF$34,4,FALSE),"") | V21: C.I. | AB21: Excentricidad (capacidad máxima menor o igual a 30 kg) | AC21: =CONCATENATE("NO CUMPLE con el ",AD21, " ",AE21) | AD21: punto 9.1.1 para el ensayo previsto en el punto 13.3, ambos de la Resolución S.C. y N.E.I. Nº 2307/80 | AE21: (Excentricidad).
J22: =CONCATENATE('Identificación del Instrumento'!$B$19,", de la localidad de ",'Identificación del Instrumento'!$B$20,", provincia de ",'Identificación del Instrumento'!$F$20) | M22: Lugar de Ubicación del instrumento (automático) | V22: Pasaporte | AB22: Excentricidad (tolvas) | AC22: =CONCATENATE("NO CUMPLE con el ",AD22, " ",AE22) | AD22: punto 9.1.1. para el ensayo previsto en el punto 13.4.1 ambos de la Resolución S.C. y N.E.I. Nº 2307/80 | AE22: (Excentricidad).
J23: =IF(ISBLANK('Identificación del Instrumento'!$C$18),"",CONCATENATE('Identificación del Instrumento'!$C$18," de ")) | M23: Nombre específico del lugar del instrumento (automático) | AB23: Excentricidad (mayor a 30 kg que admita carga rodantes) | AC23: =CONCATENATE("NO CUMPLE con el ",AD23, " ",AE23) | AD23: punto 9.1.1. para el ensayo previsto en el punto 13.4.2.1 ambos de la Resolución S.C. y N.E.I. Nº 2307/80 | AE23: (Excentricidad).
J24: ='Acta Verificación '!J25 | AB24: Excentricidad (mayor a 30 kg que NO admita carga rodantes) | AC24: =CONCATENATE("NO CUMPLE con el ",AD24, " ",AE24) | AD24: punto 9.1.1 para el ensayo previsto en el punto 13.4.3 ambos de la Resolución S.C. y N.E.I. Nº 2307/80 | AE24: (Excentricidad).
J25: ='Acta Verificación '!J26 | AB25: Excentricidad (Balanza portatil para pesar por ejes con un único receptor de carga) | AC25: =CONCATENATE("NO CUMPLE con el ",AD25, " ",AE25) | AD25: punto 9.1.1 de la Resolución S.C. y N.E.I. Nº 2307/80 para el ensayo previsto en el punto D.2.3.2.1 de la Resolución S.C.D. y D.C. Nº 119/2001 | AE25: (Excentricidad).
J26: ='Acta Verificación '!J27 | N26: TIPOS DE COMPONENTES DE LA BALANZA | AB26: Excentricidad (Balanza portatil para pesar por ejes con dos receptores de carga) | AC26: =CONCATENATE("NO CUMPLE con el ",AD26, " ",AE26) | AD26: punto 9.1.1 de la Resolución S.C. y N.E.I. Nº 2307/80 para el ensayo previsto en el punto D.2.3.2.2 de la Resolución S.C.D. y D.C. Nº 119/2001 | AE26: (Excentricidad).
J27: ='Acta Verificación '!J28 | AB27: Excentricidad (Balanza fija para pesar por ejes con un único receptor de carga) | AC27: =CONCATENATE("NO CUMPLE con el ",AD27, " ",AE27) | AD27: punto 9.1.1 de la Resolución S.C. y N.E.I. Nº 2307/80 para el ensayo previsto en el punto D.2.3.1.1 de la Resolución S.C.D. y D.C. Nº 119/2001 | AE27: (Excentricidad).
J28: =COUNTIF(K28:K33,"=FALSO") | K28: =ISBLANK(J18) | L28: =IF('Identificación del Instrumento'!$B$17="periódica","b)","a)") | N28: PLATAFORMA | P28: INDICADOR | AB28: Excentricidad (Balanza fija para pesar por ejes con dos receptores de carga) | AC28: =CONCATENATE("NO CUMPLE con el ",AD28, " ",AE28) | AD28: punto 9.1.1 de la Resolución S.C. y N.E.I. Nº 2307/80 para el ensayo previsto en el punto D.2.3.1.2 de la Resolución S.C.D. y D.C. Nº 119/2001 | AE28: (Excentricidad).
K29: =ISBLANK(K19) | N29: =IF('Identificación del Instrumento'!$F$23="electrónica","","tipo mecánica ") | P29: =IF(ISBLANK('Identificación del Instrumento'!$F$23),"",IF('Identificación del Instrumento'!$F$23="mecánica","mecánico","electrónico")) | AB29: Otro (especificar en la celda de abajo) | AC29: DETALLAR EL MOTIVO DE LA SUSPENSIÓN EN LA CELDA INDICADA
K30: =ISBLANK(K20)
K31: =ISBLANK(J21)
K32: =AND(ISBLANK('Identificación del Instrumento'!$B$19),ISBLANK('Identificación del Instrumento'!$B$15),ISBLANK('Identificación del Instrumento'!$B$16),ISBLANK('Identificación del Instrumento'!$F$16))
A33: =CONCATENATE(N5,N6) | K33: =ISBLANK(J23)
A41: =IF($J$28=6,N7,"¡Completar datos del acta!")
A44: =IF($J$28=6,N8,"¡Completar datos del acta!")
A59: =+K19 | F59: ='Datos de Ensayos'!E4
A60: =+'Identificación del Instrumento'!C14 | F60: =+'Identificación del Instrumento'!E61

Sheet Informe Suspensión
A1: Revisó y aprobó: | C1: =CONCATENATE('Datos de Ensayos'!E3," - ",'Datos de Ensayos'!E4) | K1: FALTA DE MEDIOS | L1: La verificación programada para el día de la fecha se suspende por falta de medios para realizarla. | M1: por falta de medios para realizarla.
J2: Ö | K2: INSTRUMENTO NO APTO | L2: La verificación programada para el día de la fecha se suspende porque el instrumento no está en condiciones de ser verificado. | M2: debido a que el instrumento no está en condiciones de ser verificado.
K3: FACTORES CLIMÁTICOS | L3: suspensión sin cargo al solicitante. No se emite informe | M3: por factores climáticos adversos.
A5: INFORME DE VERIFICACIÓN
A7: =CONCATENATE("N° O.T.: ",'Identificación del Instrumento'!B4) | O7: MARGENES DE INFORME PARA J JONES
A8: =IF(OR(ISBLANK('Identificación del Instrumento'!B22),ISBLANK('Identificación del Instrumento'!D29),ISBLANK('Identificación del Instrumento'!D30),ISBLANK('Identificación del Instrumento'!F30)),"",CONCATENATE("Objeto: ",'Identificación del Instrumento'!B22,", de capacidad máxima ",'Datos de Ensayos'!I18," kg,"," mínima división ",'Datos de Ensayos'!E18," kg, clase ",'Datos de Ensayos'!J17,", de tipo ",'Datos de Ensayos'!E17,".")) | Q8: SUP 4,3 | T8: ENCAB 5
A10: =Informe!A7 | O10: IZQ 1,6 | S10: DER 1,8
A11: =Informe!A9
A12: =Informe!A10
A13: =Informe!A14 | Q13: INF 5,5 | T13: PIE 4,5
A15: =Informe!A15
J16: =IF('Acta Suspensión'!L10='Acta Suspensión'!AB29,'Acta Suspensión'!L14,(VLOOKUP('Acta Suspensión'!L10,'Acta Suspensión'!AB15:AC28,2))) | O16: ESCALA 100%
A17: =Informe!A16
A18: Determinación requerida: | C18: =IF(COUNTA('Identificación del Instrumento'!$B$22)=1,VLOOKUP('Identificación del Instrumento'!$J$22,Informe!$I$17:$J$18,2,FALSE),"")
A22: Conclusión | I22: 1 | J22: Verificación del cumplimiento con las Reglamentaciones Metrológica y Técnica correspondientes a la Resolución ex S.E.C. y N.E.I. N° 2307/1980. | U22: Párrafos de las Reglamentaciones Metrológica y Técnica, Resolución 2307/80
A23: =CONCATENATE("La verificación programada para el día de la fecha se suspende por el siguinete motivo: ",J16, ".") | I23: 2 | J23: Verificación del cumplimiento con las Reglamentaciones Metrológica y Técnica correspondientes a las Resoluciones ex S.E.C. y N.E.I. N° 2307/1980 y S.C.D. y D.C. N° 119/2001. | U23: Párrafos de las Reglamentaciones Metrológica y Técnica, Resoluciones 2307/80 y 119/2001 (*)
A24: =CONCATENATE("Fecha de la verificación: ") | D24: =Informe!D28
A25: =CONCATENATE("Fecha de emisión: ") | D25: =TODAY()
A26: Los registros de verificación se encuentran archivados en el INTI.
A28: Las mediciones involucradas en este certificado están vinculadas a los patrones de medida mantenidos en el INTI según la legislación vigente, los cuales representan a las unidades físicas de medida en concordancia con el Sistema Internacional de Unidades (SI).
A32: Usuario: | B32: =Informe!B33
B33: =Informe!B34
B34: =Informe!B35
A78: Excentricidad:
B79: 0 | C79: kg | E79: #REF! | H79: 2
A80: Se utilizó una carga aproximada de
C81: kg | E81: kg
A84: =IF(#REF!=0,"El instrumento cumple con las tolerancias establecidas en el punto 9.1.1. de la Resolución 2307 de la Secretaría de Comercio ","El instrumento no cumple con las tolerancias establecidas en el punto 9.1.1. de la Resolución 2307 de la Secretaría de Comercio")
A88: Los valores de incertidumbre de medición que aparecen en la tabla de errores de indicación fueron calculados combinando la incertidumbre de las pesas patrones, y los componentes asociados a la fidelidad y resolución de la balanza. La incertidumbre standard asociada a las combinaciones de pesas patrones utilizadas resultó siempre menor que
A94: kg, para todos los valores de carga aplicados. El componente asociado a la fidelidad fue estimado estadísticamente. El componente asociado a la resolución fue calculado considerando una distribución rectangular a partir de la mínima división de la balanza. La incertidumbre expandida informada fue calculada multiplicando la incertidumbre standard combinada por un factor de cubrimiento k = 2 lo cual corresponde a un nivel de confianza del 95% para una distribución normal.

Sheet Ensayos Efectuados
A2: ENSAYOS EFECTUADOS
A4: =CONCATENATE("Informe Nº: ",'Identificación del Instrumento'!B4," ",'Identificación del Instrumento'!A5," ",'Identificación del Instrumento'!B5) | E4: =CONCATENATE("Fecha: ", IF(COUNTA('Identificación del Instrumento'!J2)=0,"",'Identificación del Instrumento'!J2))
A5: =CONCATENATE("Realizó: ",IF(ISBLANK('Datos de Ensayos'!E3),"",'Datos de Ensayos'!E3)) | E5: =CONCATENATE("Revisó: ",(IF(ISBLANK('Datos de Ensayos'!E4),"",'Datos de Ensayos'!E4)))
A6: Los ensayos que se efectúan se realizan de acuerdo a lo establecido en el Anexo de la Resolución ex - S.E.C. y N.E.I. Nº 2307/80, y se detallan a continuación:
A7: NOTA: En los casos en que el instrumento esté provisto de dos o más dispositivos indicadores de carga, deberá completarse una planilla para cada indicador.
A8: =IF(('Identificación del Instrumento'!B17="PRIMITIVA"),"Antes de ser comparadas las indicaciones o impresiones discontinuas deben ser corregidas del error de redondeo (Punto 11 de la Resolución)", "")
B10: 1.1. El instrumento parte de cero: | E10: =IF(ISBLANK('Datos de Ensayos'!F55),"",'Datos de Ensayos'!F55)
B11: 1.2. Efecto máximo del dispositivo: | E11: =IF(COUNTA('Datos de Ensayos'!G56)=1,IF('Datos de Ensayos'!G56="x","No Aplicable",IF('Datos de Ensayos'!G56="no supera","Menor al 4%","Mayor al 4%")),"")
B12: “El efecto del dispositivo de puesta en cero debe ser como máximo igual al 4% de la capacidad máxima del instrumento”
A14: 2.- Ensayo de exactitud de las pesadas (Punto 9.1. de la Resolución).
A15: 2.1. Equipos de capacidad máxima mayor ó igual a 20.000 kg.
A16: (Efectuar 2 pesadas cada 10.000 kg o fracción mayor de 4.000 kg)
B17: Medición Nº | C17: Carga aplicada (kg) | D17: Error máximo tolerado (kg) | E17: Error verificado (kg)
B18: 1 | C18: =IF(ISNUMBER('Datos de Ensayos'!D143),'Datos de Ensayos'!D143,"") | D18: ='Datos de Ensayos'!U143 | E18: =IF('Identificación del Instrumento'!$B$17="periódica",'Datos de Ensayos'!I143,'Datos de Ensayos'!L143)
B19: =B18+1 | C19: =IF(ISNUMBER('Datos de Ensayos'!D144),'Datos de Ensayos'!D144,"") | D19: =IF(ISNUMBER(C19),CONCATENATE("±",'Datos de Ensayos'!U144),"") | E19: =IF('Identificación del Instrumento'!$B$17="periódica",'Datos de Ensayos'!I144,'Datos de Ensayos'!L144)
B20: =B19+1 | C20: =IF(ISNUMBER('Datos de Ensayos'!D145),'Datos de Ensayos'!D145,"") | D20: =IF(ISNUMBER(C20),CONCATENATE("±",'Datos de Ensayos'!U145),"") | E20: =IF('Identificación del Instrumento'!$B$17="periódica",'Datos de Ensayos'!I145,'Datos de Ensayos'!L145)
B21: =B20+1 | C21: =IF(ISNUMBER('Datos de Ensayos'!D146),'Datos de Ensayos'!D146,"") | D21: =IF(ISNUMBER(C21),CONCATENATE("±",'Datos de Ensayos'!U146),"") | E21: =IF('Identificación del Instrumento'!$B$17="periódica",'Datos de Ensayos'!I146,'Datos de Ensayos'!L146)
B22: =B21+1 | C22: =IF(ISNUMBER('Datos de Ensayos'!D147),'Datos de Ensayos'!D147,"") | D22: =IF(ISNUMBER(C22),CONCATENATE("±",'Datos de Ensayos'!U147),"") | E22: =IF('Identificación del Instrumento'!$B$17="periódica",'Datos de Ensayos'!I147,'Datos de Ensayos'!L147)
B23: =B22+1 | C23: =IF(ISNUMBER('Datos de Ensayos'!D148),'Datos de Ensayos'!D148,"") | D23: =IF(ISNUMBER(C23),CONCATENATE("±",'Datos de Ensayos'!U148),"") | E23: =IF('Identificación del Instrumento'!$B$17="periódica",'Datos de Ensayos'!I148,'Datos de Ensayos'!L148)
B24: =B23+1 | C24: =IF(ISNUMBER('Datos de Ensayos'!D149),'Datos de Ensayos'!D149,"") | D24: =IF(ISNUMBER(C24),CONCATENATE("±",'Datos de Ensayos'!U149),"") | E24: =IF('Identificación del Instrumento'!$B$17="periódica",'Datos de Ensayos'!I149,'Datos de Ensayos'!L149)
B25: =B24+1 | C25: =IF(ISNUMBER('Datos de Ensayos'!D150),'Datos de Ensayos'!D150,"") | D25: =IF(ISNUMBER(C25),CONCATENATE("±",'Datos de Ensayos'!U150),"") | E25: =IF('Identificación del Instrumento'!$B$17="periódica",'Datos de Ensayos'!I150,'Datos de Ensayos'!L150)
B26: =B25+1 | C26: =IF(ISNUMBER('Datos de Ensayos'!D151),'Datos de Ensayos'!D151,"") | D26: =IF(ISNUMBER(C26),CONCATENATE("±",'Datos de Ensayos'!U151),"") | E26: =IF('Identificación del Instrumento'!$B$17="periódica",'Datos de Ensayos'!I151,'Datos de Ensayos'!L151)
B27: =B26+1 | C27: =IF(ISNUMBER('Datos de Ensayos'!D152),'Datos de Ensayos'!D152,"") | D27: =IF(ISNUMBER(C27),CONCATENATE("±",'Datos de Ensayos'!U152),"") | E27: =IF('Identificación del Instrumento'!$B$17="periódica",'Datos de Ensayos'!I152,'Datos de Ensayos'!L152)
B28: =B27+1 | C28: =IF(ISNUMBER('Datos de Ensayos'!D153),'Datos de Ensayos'!D153,"") | D28: =IF(ISNUMBER(C28),CONCATENATE("±",'Datos de Ensayos'!U153),"") | E28: =IF('Identificación del Instrumento'!$B$17="periódica",'Datos de Ensayos'!I153,'Datos de Ensayos'!L153)
B29: =B28+1 | C29: =IF(ISNUMBER('Datos de Ensayos'!D154),'Datos de Ensayos'!D154,"") | D29: =IF(ISNUMBER(C29),CONCATENATE("±",'Datos de Ensayos'!U154),"") | E29: =IF('Identificación del Instrumento'!$B$17="periódica",'Datos de Ensayos'!I154,'Datos de Ensayos'!L154)
B30: =B29+1 | C30: =IF(ISNUMBER('Datos de Ensayos'!D155),'Datos de Ensayos'!D155,"") | D30: =IF(ISNUMBER(C30),CONCATENATE("±",'Datos de Ensayos'!U155),"") | E30: =IF('Identificación del Instrumento'!$B$17="periódica",'Datos de Ensayos'!I155,'Datos de Ensayos'!L155)
... B61: =B60+1 | C61: =IF(ISNUMBER('Datos de Ensayos'!D186),'Datos de Ensayos'!D186,"") | D61: =IF(ISNUMBER(C61),CONCATENATE("±",'Datos de Ensayos'!U186),"") | E61: =IF('Identificación del Instrumento'!$B$17="periódica",'Datos de Ensayos'!I186,'Datos de Ensayos'!L186)
B64: APLICACIÓN DE CARGA SUSTITUTA
B65: =IF(ISBLANK('Datos de Ensayos'!F208), "", "(PRIMERA)")
B66: =(COUNT(C18:C61)+1) | C66: =IF(AND(ISNUMBER('Datos de Ensayos'!D197),ISNUMBER('Datos de Ensayos'!E197)),'Datos de Ensayos'!D197,"") | D66: =IF(ISNUMBER(C66),CONCATENATE("±",'Datos de Ensayos'!O197),"") | E66: =IF('Identificación del Instrumento'!$B$17="periódica",'Datos de Ensayos'!F197,'Datos de Ensayos'!I197)
B67: =B66+1 | C67: =IF(AND(ISNUMBER('Datos de Ensayos'!D198),ISNUMBER('Datos de Ensayos'!E198)),'Datos de Ensayos'!D198,"") | D67: =IF(ISNUMBER(C67),CONCATENATE("±",'Datos de Ensayos'!O198),"") | E67: =IF('Identificación del Instrumento'!$B$17="periódica",'Datos de Ensayos'!F198,'Datos de Ensayos'!I198)
B68: =B67+1 | C68: =IF(AND(ISNUMBER('Datos de Ensayos'!D199),ISNUMBER('Datos de Ensayos'!E199)),'Datos de Ensayos'!D199,"") | D68: =IF(ISNUMBER(C68),CONCATENATE("±",'Datos de Ensayos'!O199),"") | E68: =IF('Identificación del Instrumento'!$B$17="periódica",'Datos de Ensayos'!F199,'Datos de Ensayos'!I199)
